2025-08-31 09:18:16,919 | WARNING | main | Validation error: [{'type': 'value_error', 'loc': ('body', 'email'), 'msg': 'value is not a valid email address: An email address must have an @-sign.', 'input': 'erulgmail.com', 'ctx': {'reason': 'An email address must have an @-sign.'}}]
2025-08-31 09:18:36,797 | ERROR | app.middlewares.error_handler | Unexpected error: 3 validation errors:
  {'type': 'missing', 'loc': ('response', 'email'), 'msg': 'Field required', 'input': {'status': 'success', 'message': 'Login is successfully', 'data': <User email=erul@gmail.com role=other>}}
  {'type': 'missing', 'loc': ('response', 'password'), 'msg': 'Field required', 'input': {'status': 'success', 'message': 'Login is successfully', 'data': <User email=erul@gmail.com role=other>}}
  {'type': 'missing', 'loc': ('response', 'username'), 'msg': 'Field required', 'input': {'status': 'success', 'message': 'Login is successfully', 'data': <User email=erul@gmail.com role=other>}}
Traceback (most recent call last):
  File "D:\Saas_Project\.venv\Lib\site-packages\starlette\middleware\base.py", line 151, in call_next
    message = await recv_stream.receive()
              ^^^^^^^^^^^^^^^^^^^^^^^^^^^
  File "D:\Saas_Project\.venv\Lib\site-packages\anyio\streams\memory.py", line 126, in receive
    raise EndOfStream from None
anyio.EndOfStream

During handling of the above exception, another exception occurred:

Traceback (most recent call last):
  File "D:\Saas_Project\app\middlewares\error_handler.py", line 17, in dispatch
    response = await call_next(request)
               ^^^^^^^^^^^^^^^^^^^^^^^^
  File "D:\Saas_Project\.venv\Lib\site-packages\starlette\middleware\base.py", line 159, in call_next
    raise app_exc
  File "D:\Saas_Project\.venv\Lib\site-packages\starlette\middleware\base.py", line 144, in coro
    await self.app(scope, receive_or_disconnect, send_no_error)
  File "D:\Saas_Project\.venv\Lib\site-packages\starlette\middleware\exceptions.py", line 63, in __call__
    await wrap_app_handling_exceptions(self.app, conn)(scope, receive, send)
  File "D:\Saas_Project\.venv\Lib\site-packages\starlette\_exception_handler.py", line 53, in wrapped_app
    raise exc
  File "D:\Saas_Project\.venv\Lib\site-packages\starlette\_exception_handler.py", line 42, in wrapped_app
    await app(scope, receive, sender)
  File "D:\Saas_Project\.venv\Lib\site-packages\starlette\routing.py", line 716, in __call__
    await self.middleware_stack(scope, receive, send)
  File "D:\Saas_Project\.venv\Lib\site-packages\starlette\routing.py", line 736, in app
    await route.handle(scope, receive, send)
  File "D:\Saas_Project\.venv\Lib\site-packages\starlette\routing.py", line 290, in handle
    await self.app(scope, receive, send)
  File "D:\Saas_Project\.venv\Lib\site-packages\starlette\routing.py", line 78, in app
    await wrap_app_handling_exceptions(app, request)(scope, receive, send)
  File "D:\Saas_Project\.venv\Lib\site-packages\starlette\_exception_handler.py", line 53, in wrapped_app
    raise exc
  File "D:\Saas_Project\.venv\Lib\site-packages\starlette\_exception_handler.py", line 42, in wrapped_app
    await app(scope, receive, sender)
  File "D:\Saas_Project\.venv\Lib\site-packages\starlette\routing.py", line 75, in app
    response = await f(request)
               ^^^^^^^^^^^^^^^^
  File "D:\Saas_Project\.venv\Lib\site-packages\fastapi\routing.py", line 328, in app
    content = await serialize_response(
              ^^^^^^^^^^^^^^^^^^^^^^^^^
    ...<9 lines>...
    )
    ^
  File "D:\Saas_Project\.venv\Lib\site-packages\fastapi\routing.py", line 177, in serialize_response
    raise ResponseValidationError(
        errors=_normalize_errors(errors), body=response_content
    )
fastapi.exceptions.ResponseValidationError: 3 validation errors:
  {'type': 'missing', 'loc': ('response', 'email'), 'msg': 'Field required', 'input': {'status': 'success', 'message': 'Login is successfully', 'data': <User email=erul@gmail.com role=other>}}
  {'type': 'missing', 'loc': ('response', 'password'), 'msg': 'Field required', 'input': {'status': 'success', 'message': 'Login is successfully', 'data': <User email=erul@gmail.com role=other>}}
  {'type': 'missing', 'loc': ('response', 'username'), 'msg': 'Field required', 'input': {'status': 'success', 'message': 'Login is successfully', 'data': <User email=erul@gmail.com role=other>}}

2025-08-31 09:19:34,158 | ERROR | app.middlewares.error_handler | Unexpected error: 3 validation errors:
  {'type': 'missing', 'loc': ('response', 'email'), 'msg': 'Field required', 'input': {'status': 'success', 'message': 'Login is successfully', 'data': <User email=erul@gmail.com role=other>}}
  {'type': 'missing', 'loc': ('response', 'password'), 'msg': 'Field required', 'input': {'status': 'success', 'message': 'Login is successfully', 'data': <User email=erul@gmail.com role=other>}}
  {'type': 'missing', 'loc': ('response', 'username'), 'msg': 'Field required', 'input': {'status': 'success', 'message': 'Login is successfully', 'data': <User email=erul@gmail.com role=other>}}
Traceback (most recent call last):
  File "D:\Saas_Project\.venv\Lib\site-packages\starlette\middleware\base.py", line 151, in call_next
    message = await recv_stream.receive()
              ^^^^^^^^^^^^^^^^^^^^^^^^^^^
  File "D:\Saas_Project\.venv\Lib\site-packages\anyio\streams\memory.py", line 126, in receive
    raise EndOfStream from None
anyio.EndOfStream

During handling of the above exception, another exception occurred:

Traceback (most recent call last):
  File "D:\Saas_Project\app\middlewares\error_handler.py", line 17, in dispatch
    response = await call_next(request)
               ^^^^^^^^^^^^^^^^^^^^^^^^
  File "D:\Saas_Project\.venv\Lib\site-packages\starlette\middleware\base.py", line 159, in call_next
    raise app_exc
  File "D:\Saas_Project\.venv\Lib\site-packages\starlette\middleware\base.py", line 144, in coro
    await self.app(scope, receive_or_disconnect, send_no_error)
  File "D:\Saas_Project\.venv\Lib\site-packages\starlette\middleware\exceptions.py", line 63, in __call__
    await wrap_app_handling_exceptions(self.app, conn)(scope, receive, send)
  File "D:\Saas_Project\.venv\Lib\site-packages\starlette\_exception_handler.py", line 53, in wrapped_app
    raise exc
  File "D:\Saas_Project\.venv\Lib\site-packages\starlette\_exception_handler.py", line 42, in wrapped_app
    await app(scope, receive, sender)
  File "D:\Saas_Project\.venv\Lib\site-packages\starlette\routing.py", line 716, in __call__
    await self.middleware_stack(scope, receive, send)
  File "D:\Saas_Project\.venv\Lib\site-packages\starlette\routing.py", line 736, in app
    await route.handle(scope, receive, send)
  File "D:\Saas_Project\.venv\Lib\site-packages\starlette\routing.py", line 290, in handle
    await self.app(scope, receive, send)
  File "D:\Saas_Project\.venv\Lib\site-packages\starlette\routing.py", line 78, in app
    await wrap_app_handling_exceptions(app, request)(scope, receive, send)
  File "D:\Saas_Project\.venv\Lib\site-packages\starlette\_exception_handler.py", line 53, in wrapped_app
    raise exc
  File "D:\Saas_Project\.venv\Lib\site-packages\starlette\_exception_handler.py", line 42, in wrapped_app
    await app(scope, receive, sender)
  File "D:\Saas_Project\.venv\Lib\site-packages\starlette\routing.py", line 75, in app
    response = await f(request)
               ^^^^^^^^^^^^^^^^
  File "D:\Saas_Project\.venv\Lib\site-packages\fastapi\routing.py", line 328, in app
    content = await serialize_response(
              ^^^^^^^^^^^^^^^^^^^^^^^^^
    ...<9 lines>...
    )
    ^
  File "D:\Saas_Project\.venv\Lib\site-packages\fastapi\routing.py", line 177, in serialize_response
    raise ResponseValidationError(
        errors=_normalize_errors(errors), body=response_content
    )
fastapi.exceptions.ResponseValidationError: 3 validation errors:
  {'type': 'missing', 'loc': ('response', 'email'), 'msg': 'Field required', 'input': {'status': 'success', 'message': 'Login is successfully', 'data': <User email=erul@gmail.com role=other>}}
  {'type': 'missing', 'loc': ('response', 'password'), 'msg': 'Field required', 'input': {'status': 'success', 'message': 'Login is successfully', 'data': <User email=erul@gmail.com role=other>}}
  {'type': 'missing', 'loc': ('response', 'username'), 'msg': 'Field required', 'input': {'status': 'success', 'message': 'Login is successfully', 'data': <User email=erul@gmail.com role=other>}}

2025-08-31 09:19:38,428 | ERROR | app.middlewares.error_handler | Unexpected error: 3 validation errors:
  {'type': 'missing', 'loc': ('response', 'email'), 'msg': 'Field required', 'input': {'status': 'success', 'message': 'Login is successfully', 'data': <User email=erul@gmail.com role=other>}}
  {'type': 'missing', 'loc': ('response', 'password'), 'msg': 'Field required', 'input': {'status': 'success', 'message': 'Login is successfully', 'data': <User email=erul@gmail.com role=other>}}
  {'type': 'missing', 'loc': ('response', 'username'), 'msg': 'Field required', 'input': {'status': 'success', 'message': 'Login is successfully', 'data': <User email=erul@gmail.com role=other>}}
Traceback (most recent call last):
  File "D:\Saas_Project\.venv\Lib\site-packages\starlette\middleware\base.py", line 151, in call_next
    message = await recv_stream.receive()
              ^^^^^^^^^^^^^^^^^^^^^^^^^^^
  File "D:\Saas_Project\.venv\Lib\site-packages\anyio\streams\memory.py", line 126, in receive
    raise EndOfStream from None
anyio.EndOfStream

During handling of the above exception, another exception occurred:

Traceback (most recent call last):
  File "D:\Saas_Project\app\middlewares\error_handler.py", line 17, in dispatch
    response = await call_next(request)
               ^^^^^^^^^^^^^^^^^^^^^^^^
  File "D:\Saas_Project\.venv\Lib\site-packages\starlette\middleware\base.py", line 159, in call_next
    raise app_exc
  File "D:\Saas_Project\.venv\Lib\site-packages\starlette\middleware\base.py", line 144, in coro
    await self.app(scope, receive_or_disconnect, send_no_error)
  File "D:\Saas_Project\.venv\Lib\site-packages\starlette\middleware\exceptions.py", line 63, in __call__
    await wrap_app_handling_exceptions(self.app, conn)(scope, receive, send)
  File "D:\Saas_Project\.venv\Lib\site-packages\starlette\_exception_handler.py", line 53, in wrapped_app
    raise exc
  File "D:\Saas_Project\.venv\Lib\site-packages\starlette\_exception_handler.py", line 42, in wrapped_app
    await app(scope, receive, sender)
  File "D:\Saas_Project\.venv\Lib\site-packages\starlette\routing.py", line 716, in __call__
    await self.middleware_stack(scope, receive, send)
  File "D:\Saas_Project\.venv\Lib\site-packages\starlette\routing.py", line 736, in app
    await route.handle(scope, receive, send)
  File "D:\Saas_Project\.venv\Lib\site-packages\starlette\routing.py", line 290, in handle
    await self.app(scope, receive, send)
  File "D:\Saas_Project\.venv\Lib\site-packages\starlette\routing.py", line 78, in app
    await wrap_app_handling_exceptions(app, request)(scope, receive, send)
  File "D:\Saas_Project\.venv\Lib\site-packages\starlette\_exception_handler.py", line 53, in wrapped_app
    raise exc
  File "D:\Saas_Project\.venv\Lib\site-packages\starlette\_exception_handler.py", line 42, in wrapped_app
    await app(scope, receive, sender)
  File "D:\Saas_Project\.venv\Lib\site-packages\starlette\routing.py", line 75, in app
    response = await f(request)
               ^^^^^^^^^^^^^^^^
  File "D:\Saas_Project\.venv\Lib\site-packages\fastapi\routing.py", line 328, in app
    content = await serialize_response(
              ^^^^^^^^^^^^^^^^^^^^^^^^^
    ...<9 lines>...
    )
    ^
  File "D:\Saas_Project\.venv\Lib\site-packages\fastapi\routing.py", line 177, in serialize_response
    raise ResponseValidationError(
        errors=_normalize_errors(errors), body=response_content
    )
fastapi.exceptions.ResponseValidationError: 3 validation errors:
  {'type': 'missing', 'loc': ('response', 'email'), 'msg': 'Field required', 'input': {'status': 'success', 'message': 'Login is successfully', 'data': <User email=erul@gmail.com role=other>}}
  {'type': 'missing', 'loc': ('response', 'password'), 'msg': 'Field required', 'input': {'status': 'success', 'message': 'Login is successfully', 'data': <User email=erul@gmail.com role=other>}}
  {'type': 'missing', 'loc': ('response', 'username'), 'msg': 'Field required', 'input': {'status': 'success', 'message': 'Login is successfully', 'data': <User email=erul@gmail.com role=other>}}

2025-08-31 09:27:14,520 | ERROR | app.middlewares.error_handler | Unexpected error: 1 validation errors:
  {'type': 'dict_type', 'loc': ('response', 'data'), 'msg': 'Input should be a valid dictionary', 'input': <User email=erul@gmail.com role=other>}
Traceback (most recent call last):
  File "D:\Saas_Project\.venv\Lib\site-packages\starlette\middleware\base.py", line 151, in call_next
    message = await recv_stream.receive()
              ^^^^^^^^^^^^^^^^^^^^^^^^^^^
  File "D:\Saas_Project\.venv\Lib\site-packages\anyio\streams\memory.py", line 126, in receive
    raise EndOfStream from None
anyio.EndOfStream

During handling of the above exception, another exception occurred:

Traceback (most recent call last):
  File "D:\Saas_Project\app\middlewares\error_handler.py", line 17, in dispatch
    response = await call_next(request)
               ^^^^^^^^^^^^^^^^^^^^^^^^
  File "D:\Saas_Project\.venv\Lib\site-packages\starlette\middleware\base.py", line 159, in call_next
    raise app_exc
  File "D:\Saas_Project\.venv\Lib\site-packages\starlette\middleware\base.py", line 144, in coro
    await self.app(scope, receive_or_disconnect, send_no_error)
  File "D:\Saas_Project\.venv\Lib\site-packages\starlette\middleware\exceptions.py", line 63, in __call__
    await wrap_app_handling_exceptions(self.app, conn)(scope, receive, send)
  File "D:\Saas_Project\.venv\Lib\site-packages\starlette\_exception_handler.py", line 53, in wrapped_app
    raise exc
  File "D:\Saas_Project\.venv\Lib\site-packages\starlette\_exception_handler.py", line 42, in wrapped_app
    await app(scope, receive, sender)
  File "D:\Saas_Project\.venv\Lib\site-packages\starlette\routing.py", line 716, in __call__
    await self.middleware_stack(scope, receive, send)
  File "D:\Saas_Project\.venv\Lib\site-packages\starlette\routing.py", line 736, in app
    await route.handle(scope, receive, send)
  File "D:\Saas_Project\.venv\Lib\site-packages\starlette\routing.py", line 290, in handle
    await self.app(scope, receive, send)
  File "D:\Saas_Project\.venv\Lib\site-packages\starlette\routing.py", line 78, in app
    await wrap_app_handling_exceptions(app, request)(scope, receive, send)
  File "D:\Saas_Project\.venv\Lib\site-packages\starlette\_exception_handler.py", line 53, in wrapped_app
    raise exc
  File "D:\Saas_Project\.venv\Lib\site-packages\starlette\_exception_handler.py", line 42, in wrapped_app
    await app(scope, receive, sender)
  File "D:\Saas_Project\.venv\Lib\site-packages\starlette\routing.py", line 75, in app
    response = await f(request)
               ^^^^^^^^^^^^^^^^
  File "D:\Saas_Project\.venv\Lib\site-packages\fastapi\routing.py", line 328, in app
    content = await serialize_response(
              ^^^^^^^^^^^^^^^^^^^^^^^^^
    ...<9 lines>...
    )
    ^
  File "D:\Saas_Project\.venv\Lib\site-packages\fastapi\routing.py", line 177, in serialize_response
    raise ResponseValidationError(
        errors=_normalize_errors(errors), body=response_content
    )
fastapi.exceptions.ResponseValidationError: 1 validation errors:
  {'type': 'dict_type', 'loc': ('response', 'data'), 'msg': 'Input should be a valid dictionary', 'input': <User email=erul@gmail.com role=other>}

2025-08-31 09:28:58,906 | ERROR | app.middlewares.error_handler | Unexpected error: 1 validation errors:
  {'type': 'dict_type', 'loc': ('response', 'data'), 'msg': 'Input should be a valid dictionary', 'input': <User email=erul@gmail.com role=other>}
Traceback (most recent call last):
  File "D:\Saas_Project\.venv\Lib\site-packages\starlette\middleware\base.py", line 151, in call_next
    message = await recv_stream.receive()
              ^^^^^^^^^^^^^^^^^^^^^^^^^^^
  File "D:\Saas_Project\.venv\Lib\site-packages\anyio\streams\memory.py", line 126, in receive
    raise EndOfStream from None
anyio.EndOfStream

During handling of the above exception, another exception occurred:

Traceback (most recent call last):
  File "D:\Saas_Project\app\middlewares\error_handler.py", line 17, in dispatch
    response = await call_next(request)
               ^^^^^^^^^^^^^^^^^^^^^^^^
  File "D:\Saas_Project\.venv\Lib\site-packages\starlette\middleware\base.py", line 159, in call_next
    raise app_exc
  File "D:\Saas_Project\.venv\Lib\site-packages\starlette\middleware\base.py", line 144, in coro
    await self.app(scope, receive_or_disconnect, send_no_error)
  File "D:\Saas_Project\.venv\Lib\site-packages\starlette\middleware\exceptions.py", line 63, in __call__
    await wrap_app_handling_exceptions(self.app, conn)(scope, receive, send)
  File "D:\Saas_Project\.venv\Lib\site-packages\starlette\_exception_handler.py", line 53, in wrapped_app
    raise exc
  File "D:\Saas_Project\.venv\Lib\site-packages\starlette\_exception_handler.py", line 42, in wrapped_app
    await app(scope, receive, sender)
  File "D:\Saas_Project\.venv\Lib\site-packages\starlette\routing.py", line 716, in __call__
    await self.middleware_stack(scope, receive, send)
  File "D:\Saas_Project\.venv\Lib\site-packages\starlette\routing.py", line 736, in app
    await route.handle(scope, receive, send)
  File "D:\Saas_Project\.venv\Lib\site-packages\starlette\routing.py", line 290, in handle
    await self.app(scope, receive, send)
  File "D:\Saas_Project\.venv\Lib\site-packages\starlette\routing.py", line 78, in app
    await wrap_app_handling_exceptions(app, request)(scope, receive, send)
  File "D:\Saas_Project\.venv\Lib\site-packages\starlette\_exception_handler.py", line 53, in wrapped_app
    raise exc
  File "D:\Saas_Project\.venv\Lib\site-packages\starlette\_exception_handler.py", line 42, in wrapped_app
    await app(scope, receive, sender)
  File "D:\Saas_Project\.venv\Lib\site-packages\starlette\routing.py", line 75, in app
    response = await f(request)
               ^^^^^^^^^^^^^^^^
  File "D:\Saas_Project\.venv\Lib\site-packages\fastapi\routing.py", line 328, in app
    content = await serialize_response(
              ^^^^^^^^^^^^^^^^^^^^^^^^^
    ...<9 lines>...
    )
    ^
  File "D:\Saas_Project\.venv\Lib\site-packages\fastapi\routing.py", line 177, in serialize_response
    raise ResponseValidationError(
        errors=_normalize_errors(errors), body=response_content
    )
fastapi.exceptions.ResponseValidationError: 1 validation errors:
  {'type': 'dict_type', 'loc': ('response', 'data'), 'msg': 'Input should be a valid dictionary', 'input': <User email=erul@gmail.com role=other>}

2025-08-31 09:29:09,847 | ERROR | app.middlewares.error_handler | Unexpected error: 'User' object has no attribute 'model_dump'
Traceback (most recent call last):
  File "D:\Saas_Project\.venv\Lib\site-packages\starlette\middleware\base.py", line 151, in call_next
    message = await recv_stream.receive()
              ^^^^^^^^^^^^^^^^^^^^^^^^^^^
  File "D:\Saas_Project\.venv\Lib\site-packages\anyio\streams\memory.py", line 126, in receive
    raise EndOfStream from None
anyio.EndOfStream

During handling of the above exception, another exception occurred:

Traceback (most recent call last):
  File "D:\Saas_Project\app\middlewares\error_handler.py", line 17, in dispatch
    response = await call_next(request)
               ^^^^^^^^^^^^^^^^^^^^^^^^
  File "D:\Saas_Project\.venv\Lib\site-packages\starlette\middleware\base.py", line 159, in call_next
    raise app_exc
  File "D:\Saas_Project\.venv\Lib\site-packages\starlette\middleware\base.py", line 144, in coro
    await self.app(scope, receive_or_disconnect, send_no_error)
  File "D:\Saas_Project\.venv\Lib\site-packages\starlette\middleware\exceptions.py", line 63, in __call__
    await wrap_app_handling_exceptions(self.app, conn)(scope, receive, send)
  File "D:\Saas_Project\.venv\Lib\site-packages\starlette\_exception_handler.py", line 53, in wrapped_app
    raise exc
  File "D:\Saas_Project\.venv\Lib\site-packages\starlette\_exception_handler.py", line 42, in wrapped_app
    await app(scope, receive, sender)
  File "D:\Saas_Project\.venv\Lib\site-packages\starlette\routing.py", line 716, in __call__
    await self.middleware_stack(scope, receive, send)
  File "D:\Saas_Project\.venv\Lib\site-packages\starlette\routing.py", line 736, in app
    await route.handle(scope, receive, send)
  File "D:\Saas_Project\.venv\Lib\site-packages\starlette\routing.py", line 290, in handle
    await self.app(scope, receive, send)
  File "D:\Saas_Project\.venv\Lib\site-packages\starlette\routing.py", line 78, in app
    await wrap_app_handling_exceptions(app, request)(scope, receive, send)
  File "D:\Saas_Project\.venv\Lib\site-packages\starlette\_exception_handler.py", line 53, in wrapped_app
    raise exc
  File "D:\Saas_Project\.venv\Lib\site-packages\starlette\_exception_handler.py", line 42, in wrapped_app
    await app(scope, receive, sender)
  File "D:\Saas_Project\.venv\Lib\site-packages\starlette\routing.py", line 75, in app
    response = await f(request)
               ^^^^^^^^^^^^^^^^
  File "D:\Saas_Project\.venv\Lib\site-packages\fastapi\routing.py", line 302, in app
    raw_response = await run_endpoint_function(
                   ^^^^^^^^^^^^^^^^^^^^^^^^^^^^
    ...<3 lines>...
    )
    ^
  File "D:\Saas_Project\.venv\Lib\site-packages\fastapi\routing.py", line 215, in run_endpoint_function
    return await run_in_threadpool(dependant.call, **values)
           ^^^^^^^^^^^^^^^^^^^^^^^^^^^^^^^^^^^^^^^^^^^^^^^^^
  File "D:\Saas_Project\.venv\Lib\site-packages\starlette\concurrency.py", line 38, in run_in_threadpool
    return await anyio.to_thread.run_sync(func)
           ^^^^^^^^^^^^^^^^^^^^^^^^^^^^^^^^^^^^
  File "D:\Saas_Project\.venv\Lib\site-packages\anyio\to_thread.py", line 56, in run_sync
    return await get_async_backend().run_sync_in_worker_thread(
           ^^^^^^^^^^^^^^^^^^^^^^^^^^^^^^^^^^^^^^^^^^^^^^^^^^^^
        func, args, abandon_on_cancel=abandon_on_cancel, limiter=limiter
        ^^^^^^^^^^^^^^^^^^^^^^^^^^^^^^^^^^^^^^^^^^^^^^^^^^^^^^^^^^^^^^^^
    )
    ^
  File "D:\Saas_Project\.venv\Lib\site-packages\anyio\_backends\_asyncio.py", line 2476, in run_sync_in_worker_thread
    return await future
           ^^^^^^^^^^^^
  File "D:\Saas_Project\.venv\Lib\site-packages\anyio\_backends\_asyncio.py", line 967, in run
    result = context.run(func, *args)
  File "D:\Saas_Project\app\routes\auth_route.py", line 16, in login
    return success_response("Login is successfully", user.model_dump())
                                                     ^^^^^^^^^^^^^^^
AttributeError: 'User' object has no attribute 'model_dump'
2025-08-31 11:29:59,176 | WARNING | app.dependencies.auth | Access attempt without token
2025-08-31 11:30:22,213 | WARNING | main | Validation error: [{'type': 'missing', 'loc': ('body', 'name'), 'msg': 'Field required', 'input': {'email': 'erul@gmail.com', 'password': '12345678'}}]
2025-08-31 11:39:17,316 | WARNING | app.controllers.auth_controller | Invalid login attempt for email: erul@gmail.com
2025-08-31 11:39:58,609 | WARNING | app.controllers.auth_controller | Invalid login attempt for email: erul@gmail.com
